Workbook

Sheet Матрица с индикаторами
A1: Индекс | B1: Содержание | C1: Философия | D1: История (история России, всеобщая история) | E1: Иностранный язык | F1: Безопасность жизнедеятельности | G1: Физическая культура и спорт | H1: Информатика | I1: Цифровые технологии самообразования | J1: Религии мира | K1: Тренинг-практикум по самоорганизации и саморазвитию | L1: Физика | M1: Химия | N1: Математика | O1: Русский язык и деловые коммуникации | P1: Общий курс транспорта | Q1: Организация доступной среды | R1: Правовое обеспечение профессиональной деятельности | S1: Инженерная и компьютерная графика | T1: Экономика | U1: Экология | V1: Менеджмент | W1: Метрология, стандартизация и сертификация | X1: Транспортно-технологические системы | Y1: Системы искусственного интеллекта | Z1: Информационные технологии на транспорте. Цифровизация технологических процессов | AA1: Математическое моделирование транспортных процессов | AB1: Менеджмент качества и эффективность технических и технологических мероприятий в транспортных процессах | AC1: История России | AD1: Элективные курсы по физической культуре и спорту | AE1: Теория и практика логистики | AF1: Управление грузовой и коммерческой работой. Грузоведение | AG1: Транспортная логистика | AH1: Промышленный транспорт | AI1: Организация движения на железнодорожном транспорте | AJ1: Железнодорожная транспортная инфраструктура | AK1: Управление эксплуатационной работой | AL1: Организация логистики пассажирских перевозок | AM1: Обеспечение безопасности на транспорте | AN1: Хладотранспорт и основы теплотехники | AO1: Организация перевозок скоропортящихся грузов | AP1: Основы транспортного бизнеса | AQ1: Аутсорсинг на транспорте | AR1: Организация контейнерных и пакетных перевозок | AS1: Терминальные системы транспорта | AT1: Организация перевозок и тарифы в международных сообщениях | AU1: Организация мультимодальных перевозок | AV1: Организация работы экспедиторских фирм | AW1: Сервис на транспорте | AX1: Учебная практика (ознакомительная практика) | AY1: Производственная практика (технологическая (производственно-технологическая) практика) | AZ1: Производственная практика (эксплуатационная практика) | BA1: Производственная практика (преддипломная практика) | BB1: Итого без учета факультативов | BC1: История религиозной культуры | BD1: Построение бизнес-модели | BE1: Итого для факультативов | BF1: Итого
C2: Б1.О.01 | D2: Б1.О.02 | E2: Б1.О.03 | F2: Б1.О.04 | G2: Б1.О.05 | H2: Б1.О.06.01 | I2: Б1.О.06.02 | J2: Б1.О.07 | K2: Б1.О.08 | L2: Б1.О.09 | M2: Б1.О.10 | N2: Б1.О.11 | O2: Б1.О.12 | P2: Б1.О.13 | Q2: Б1.О.14 | R2: Б1.О.15 | S2: Б1.О.16 | T2: Б1.О.17 | U2: Б1.О.18 | V2: Б1.О.19 | W2: Б1.О.20 | X2: Б1.О.21 | Y2: Б1.О.22.01 | Z2: Б1.О.22.02 | AA2: Б1.О.23 | AB2: Б1.О.24 | AC2: Б1.О.25 | AD2: Б1.В.01.01 | AE2: Б1.В.02 | AF2: Б1.В.03 | AG2: Б1.В.04 | AH2: Б1.В.05 | AI2: Б1.В.06 | AJ2: Б1.В.07 | AK2: Б1.В.08 | AL2: Б1.В.09 | AM2: Б1.В.10 | AN2: Б1.В.ДВ.01.01 | AO2: Б1.В.ДВ.01.02 | AP2: Б1.В.ДВ.02.01 | AQ2: Б1.В.ДВ.02.02 | AR2: Б1.В.ДВ.03.01 | AS2: Б1.В.ДВ.03.02 | AT2: Б1.В.ДВ.04.01 | AU2: Б1.В.ДВ.04.02 | AV2: Б1.В.ДВ.05.01 | AW2: Б1.В.ДВ.05.02 | AX2: Б2.О.01(У) | AY2: Б2.В.01(П) | AZ2: Б2.В.02(П) | BA2: Б2.В.03(Пд) | BC2: ФТД.01 | BD2: ФТД.02
C3: УК-1.1; УК-1.2 | D3: УК-5.1; УК-5.2 | E3: УК-4.3; УК-4.4 | F3: УК-8.1; УК-8.2; УК-8.3 | G3: УК-7.1; УК-7.2 | H3: ОПК-4.1 | I3: ОПК-4.2 | J3: УК-5.3 | K3: УК-6.1; УК-6.2 | L3: ОПК-1.2; ОПК-1.3 | M3: ОПК-1.2; ОПК-1.3 | N3: ОПК-1.1 | O3: УК-4.1; УК-4.2 | P3: ОПК-5.3 | Q3: УК-9.1; УК-9.2 | R3: УК-2.1; УК-11.1; УК-11.2 | S3: ОПК-1.4 | T3: УК-10.1; УК-10.2; ОПК-2.2 | U3: ОПК-2.1 | V3: УК-2.2; УК-3.1; УК-3.2; ОПК-2.3 | W3: ОПК-3.1; ОПК-3.2; ОПК-6.2 | X3: ОПК-2.4; ОПК-5.2 | Y3: ОПК-4.4 | Z3: ОПК-4.2; ОПК-4.3 | AA3: ОПК-1.5; ПК-5.1 | AB3: ОПК-5.1; ОПК-6.1; ПК-5.3 | AC3: УК-2.1; УК-5.1; УК-5.2 | AD3: УК-7.3 | AE3: ПК-5.5 | AF3: ПК-1.1; ПК-1.2 | AG3: ПК-5.2 | AH3: ПК-4.2 | AI3: ПК-2.4 | AJ3: ПК-3.1; ПК-3.2 | AK3: ПК-2.1 | AL3: ПК-6.1; ПК-6.2 | AM3: ПК-2.2; ПК-2.3 | AN3: ПК-1.3 | AO3: ПК-1.3 | AP3: ПК-4.3; ПК-4.4 | AQ3: ПК-4.3; ПК-4.4 | AR3: ПК-5.4 | AS3: ПК-5.4 | AT3: ПК-1.4 | AU3: ПК-1.4 | AV3: ПК-4.1 | AW3: ПК-4.1 | AX3: ОПК-5.3; ПК-5.5 | AY3: ПК-1.2; ПК-2.1; ПК-3.1; ПК-3.2; ПК-5.2 | AZ3: ПК-1.1; ПК-1.3; ПК-2.4; ПК-4.1; ПК-4.4; ПК-5.4; ПК-5.5 | BA3: ПК-1.4; ПК-2.2; ПК-2.3; ПК-4.2; ПК-4.3; ПК-5.1; ПК-5.3; ПК-6.1; ПК-6.2 | BC3: УК-5.3 | BD3: УК-2.2
A4: УК-1 | B4: =VLOOKUP(A4,Лист1!B:C,2,0) -> Способен осуществлять поиск, критический анализ и синтез информации, применять системный подход для решения поставленных задач | C4: 18 | D4: =IFERROR(IF(SEARCH($A4,D$3)<>0,1,""),"") | E4: =IFERROR(IF(SEARCH($A4,E$3)<>0,1,""),"") | F4: =IFERROR(IF(SEARCH($A4,F$3)<>0,1,""),"") | G4: =IFERROR(IF(SEARCH($A4,G$3)<>0,1,""),"") | H4: =IFERROR(IF(SEARCH($A4,H$3)<>0,1,""),"") | I4: =IFERROR(IF(SEARCH($A4,I$3)<>0,1,""),"") | J4: =IFERROR(IF(SEARCH($A4,J$3)<>0,1,""),"") | K4: =IFERROR(IF(SEARCH($A4,K$3)<>0,1,""),"") | ... Q4: =IFERROR(IF(SEARCH($A4,Q$3)<>0,1,""),"") | S4: =IFERROR(IF(SEARCH($A4,S$3)<>0,1,""),"") | U4: =IFERROR(IF(SEARCH($A4,U$3)<>0,1,""),"") | V4: =IFERROR(IF(SEARCH($A4,V$3)<>0,1,""),"") | W4: =IFERROR(IF(SEARCH($A4,W$3)<>0,1,""),"") | X4: =IFERROR(IF(SEARCH($A4,X$3)<>0,1,""),"") | Y4: =IFERROR(IF(SEARCH($A4,Y$3)<>0,1,""),"") | Z4: =IFERROR(IF(SEARCH($A4,Z$3)<>0,1,""),"") | AA4: =IFERROR(IF(SEARCH($A4,AA$3)<>0,1,""),"") | AB4: =IFERROR(IF(SEARCH($A4,AB$3)<>0,1,""),"") | ... BA4: =IFERROR(IF(SEARCH($A4,BA$3)<>0,1,""),"") | BB4: =SUM(C4:BA4) -> 18 | BE4: =SUM(BC4:BD4) -> 0 | BF4: =BB4+BE4 -> 18
A5: УК-1.1 | B5: =VLOOKUP(A5,Лист1!B:C,2,0) -> Осуществляет поиск информации, критически оценивает надежность источников информации, работает с противоречивой информацией из разных источников | C5: 9 | D5: =IFERROR(SEARCH($A5,D$3),"") | E5: =IFERROR(SEARCH($A5,E$3),"") | F5: =IFERROR(SEARCH($A5,F$3),"") | G5: =IFERROR(SEARCH($A5,G$3),"") | H5: =IFERROR(SEARCH($A5,H$3),"") | I5: =IFERROR(SEARCH($A5,I$3),"") | J5: =IFERROR(SEARCH($A5,J$3),"") | K5: =IFERROR(SEARCH($A5,K$3),"") | ... BA5: =IFERROR(SEARCH($A5,BA$3),"") | BB5: =SUM(C5:BA5) -> 9 | BC5: =IFERROR(SEARCH($A5,BC$3),"") | BD5: =IFERROR(SEARCH($A5,BD$3),"") | BE5: =SUM(BC5:BD5) -> 0 | BF5: =BB5+BE5 -> 9
A6: УК-1.2 | B6: =VLOOKUP(A6,Лист1!B:C,2,0) -> Анализирует проблемную ситуацию, выявляет ее составляющие и связи между ними, формулирует и аргументирует выводы и суждения | C6: 9 | D6: =IFERROR(SEARCH($A6,D$3),"") | E6: =IFERROR(SEARCH($A6,E$3),"") | F6: =IFERROR(SEARCH($A6,F$3),"") | G6: =IFERROR(SEARCH($A6,G$3),"") | H6: =IFERROR(SEARCH($A6,H$3),"") | I6: =IFERROR(SEARCH($A6,I$3),"") | J6: =IFERROR(SEARCH($A6,J$3),"") | K6: =IFERROR(SEARCH($A6,K$3),"") | ... BA6: =IFERROR(SEARCH($A6,BA$3),"") | BB6: =SUM(C6:BA6) -> 9 | BC6: =IFERROR(SEARCH($A6,BC$3),"") | BD6: =IFERROR(SEARCH($A6,BD$3),"") | BE6: =SUM(BC6:BD6) -> 0 | BF6: =BB6+BE6 -> 9
A7: УК-2 | B7: =VLOOKUP(A7,Лист1!B:C,2,0) -> Способен определять круг задач в рамках поставленной цели и выбирать оптимальные способы их решения, исходя из действующих правовых норм, имеющихся ресурсов и ограничений | C7: =IFERROR(IF(SEARCH($A7,C$3)<>0,1,""),"") | D7: =IFERROR(IF(SEARCH($A7,D$3)<>0,1,""),"") | E7: =IFERROR(IF(SEARCH($A7,E$3)<>0,1,""),"") | F7: =IFERROR(IF(SEARCH($A7,F$3)<>0,1,""),"") | G7: =IFERROR(IF(SEARCH($A7,G$3)<>0,1,""),"") | H7: =IFERROR(IF(SEARCH($A7,H$3)<>0,1,""),"") | I7: =IFERROR(IF(SEARCH($A7,I$3)<>0,1,""),"") | J7: =IFERROR(IF(SEARCH($A7,J$3)<>0,1,""),"") | ... Q7: =IFERROR(IF(SEARCH($A7,Q$3)<>0,1,""),"") | R7: 2 | S7: =IFERROR(IF(SEARCH($A7,S$3)<>0,1,""),"") | T7: =IFERROR(IF(SEARCH($A7,T$3)<>0,1,""),"") | U7: =IFERROR(IF(SEARCH($A7,U$3)<>0,1,""),"") | V7: 2 | W7: =IFERROR(IF(SEARCH($A7,W$3)<>0,1,""),"") | X7: =IFERROR(IF(SEARCH($A7,X$3)<>0,1,""),"") | Y7: =IFERROR(IF(SEARCH($A7,Y$3)<>0,1,""),"") | Z7: =IFERROR(IF(SEARCH($A7,Z$3)<>0,1,""),"") | AA7: =IFERROR(IF(SEARCH($A7,AA$3)<>0,1,""),"") | AB7: =IFERROR(IF(SEARCH($A7,AB$3)<>0,1,""),"") | AC7: 14 | AD7: =IFERROR(IF(SEARCH($A7,AD$3)<>0,1,""),"") | AE7: =IFERROR(IF(SEARCH($A7,AE$3)<>0,1,""),"") | AF7: =IFERROR(IF(SEARCH($A7,AF$3)<>0,1,""),"") | AG7: =IFERROR(IF(SEARCH($A7,AG$3)<>0,1,""),"") | AH7: =IFERROR(IF(SEARCH($A7,AH$3)<>0,1,""),"") | AI7: =IFERROR(IF(SEARCH($A7,AI$3)<>0,1,""),"") | AJ7: =IFERROR(IF(SEARCH($A7,AJ$3)<>0,1,""),"") | AK7: =IFERROR(IF(SEARCH($A7,AK$3)<>0,1,""),"") | ... BA7: =IFERROR(IF(SEARCH($A7,BA$3)<>0,1,""),"") | BB7: =SUM(C7:BA7) -> 18 | BC7: =IFERROR(SEARCH(_xlfn.CONCAT(" ",$A7),#REF!),"") | BD7: 18 | BE7: =SUM(BC7:BD7) -> 18 | BF7: =BB7+BE7 -> 36
A8: УК-2.1 | B8: =VLOOKUP(A8,Лист1!B:C,2,0) -> Решает ситуационные задачи с учетом трудовых и социальных факторов в рамках нормативно-правового регулирования | C8: =IFERROR(SEARCH($A8,C$3),"") | D8: =IFERROR(SEARCH($A8,D$3),"") | E8: =IFERROR(SEARCH($A8,E$3),"") | F8: =IFERROR(SEARCH($A8,F$3),"") | G8: =IFERROR(SEARCH($A8,G$3),"") | H8: =IFERROR(SEARCH($A8,H$3),"") | I8: =IFERROR(SEARCH($A8,I$3),"") | J8: =IFERROR(SEARCH($A8,J$3),"") | ... Q8: =IFERROR(SEARCH($A8,Q$3),"") | R8: 2 | S8: =IFERROR(SEARCH($A8,S$3),"") | T8: =IFERROR(SEARCH($A8,T$3),"") | U8: =IFERROR(SEARCH($A8,U$3),"") | V8: =IFERROR(SEARCH($A8,V$3),"") | W8: =IFERROR(SEARCH($A8,W$3),"") | X8: =IFERROR(SEARCH($A8,X$3),"") | Y8: =IFERROR(SEARCH($A8,Y$3),"") | Z8: =IFERROR(SEARCH($A8,Z$3),"") | ... AB8: =IFERROR(SEARCH($A8,AB$3),"") | AC8: 14 | AD8: =IFERROR(SEARCH($A8,AD$3),"") | AE8: =IFERROR(SEARCH($A8,AE$3),"") | AF8: =IFERROR(SEARCH($A8,AF$3),"") | AG8: =IFERROR(SEARCH($A8,AG$3),"") | AH8: =IFERROR(SEARCH($A8,AH$3),"") | AI8: =IFERROR(SEARCH($A8,AI$3),"") | AJ8: =IFERROR(SEARCH($A8,AJ$3),"") | AK8: =IFERROR(SEARCH($A8,AK$3),"") | ... BA8: =IFERROR(SEARCH($A8,BA$3),"") | BB8: =SUM(C8:BA8) -> 16 | BC8: =IFERROR(SEARCH($A8,BC$3),"") | BD8: =IFERROR(SEARCH($A8,BD$3),"") | BE8: =SUM(BC8:BD8) -> 0 | BF8: =BB8+BE8 -> 16
A9: УК-2.2 | B9: =VLOOKUP(A9,Лист1!B:C,2,0) -> Формулирует проектную задачу, определяет способы ее решения средствами проектного управления | C9: =IFERROR(SEARCH($A9,C$3),"") | D9: =IFERROR(SEARCH($A9,D$3),"") | E9: =IFERROR(SEARCH($A9,E$3),"") | F9: =IFERROR(SEARCH($A9,F$3),"") | G9: =IFERROR(SEARCH($A9,G$3),"") | H9: =IFERROR(SEARCH($A9,H$3),"") | I9: =IFERROR(SEARCH($A9,I$3),"") | J9: =IFERROR(SEARCH($A9,J$3),"") | ... U9: =IFERROR(SEARCH($A9,U$3),"") | V9: 2 | W9: =IFERROR(SEARCH($A9,W$3),"") | X9: =IFERROR(SEARCH($A9,X$3),"") | Y9: =IFERROR(SEARCH($A9,Y$3),"") | Z9: =IFERROR(SEARCH($A9,Z$3),"") | AA9: =IFERROR(SEARCH($A9,AA$3),"") | AB9: =IFERROR(SEARCH($A9,AB$3),"") | AC9: =IFERROR(SEARCH($A9,AC$3),"") | AD9: =IFERROR(SEARCH($A9,AD$3),"") | ... BA9: =IFERROR(SEARCH($A9,BA$3),"") | BB9: =SUM(C9:BA9) -> 2 | BC9: =IFERROR(SEARCH($A9,BC$3),"") | BD9: 18 | BE9: =SUM(BC9:BD9) -> 18 | BF9: =BB9+BE9 -> 20
A10: УК-3 | B10: =VLOOKUP(A10,Лист1!B:C,2,0) -> Способен осуществлять социальное взаимодействие и реализовывать свою роль в команде | C10: =IFERROR(IF(SEARCH($A10,C$3)<>0,1,""),"") | D10: =IFERROR(IF(SEARCH($A10,D$3)<>0,1,""),"") | E10: =IFERROR(IF(SEARCH($A10,E$3)<>0,1,""),"") | F10: =IFERROR(IF(SEARCH($A10,F$3)<>0,1,""),"") | G10: =IFERROR(IF(SEARCH($A10,G$3)<>0,1,""),"") | H10: =IFERROR(IF(SEARCH($A10,H$3)<>0,1,""),"") | I10: =IFERROR(IF(SEARCH($A10,I$3)<>0,1,""),"") | J10: =IFERROR(IF(SEARCH($A10,J$3)<>0,1,""),"") | ... U10: =IFERROR(IF(SEARCH($A10,U$3)<>0,1,""),"") | V10: 18 | W10: =IFERROR(IF(SEARCH($A10,W$3)<>0,1,""),"") | X10: =IFERROR(IF(SEARCH($A10,X$3)<>0,1,""),"") | Y10: =IFERROR(IF(SEARCH($A10,Y$3)<>0,1,""),"") | Z10: =IFERROR(IF(SEARCH($A10,Z$3)<>0,1,""),"") | AA10: =IFERROR(IF(SEARCH($A10,AA$3)<>0,1,""),"") | AB10: =IFERROR(IF(SEARCH($A10,AB$3)<>0,1,""),"") | AC10: =IFERROR(IF(SEARCH($A10,AC$3)<>0,1,""),"") | AD10: =IFERROR(IF(SEARCH($A10,AD$3)<>0,1,""),"") | ... BA10: =IFERROR(IF(SEARCH($A10,BA$3)<>0,1,""),"") | BB10: =SUM(C10:BA10) -> 18 | BC10: =IFERROR(SEARCH(_xlfn.CONCAT(" ",$A10),#REF!),"") | BD10: =IFERROR(SEARCH(_xlfn.CONCAT(" ",$A10),#REF!),"") | BE10: =SUM(BC10:BD10) -> 0 | BF10: =BB10+BE10 -> 18
A11: УК-3.1 | B11: =VLOOKUP(A11,Лист1!B:C,2,0) -> Организует и координирует работу команды с учетом интересов, особенностей поведения и мнения её членов | C11: =IFERROR(SEARCH($A11,C$3),"") | D11: =IFERROR(SEARCH($A11,D$3),"") | E11: =IFERROR(SEARCH($A11,E$3),"") | F11: =IFERROR(SEARCH($A11,F$3),"") | G11: =IFERROR(SEARCH($A11,G$3),"") | H11: =IFERROR(SEARCH($A11,H$3),"") | I11: =IFERROR(SEARCH($A11,I$3),"") | J11: =IFERROR(SEARCH($A11,J$3),"") | ... BA11: =IFERROR(SEARCH($A11,BA$3),"") | BB11: =SUM(C11:BA11) -> 9 | BC11: =IFERROR(SEARCH($A11,BC$3),"") | BD11: =IFERROR(SEARCH($A11,BD$3),"") | BE11: =SUM(BC11:BD11) -> 0 | BF11: =BB11+BE11 -> 9
A12: УК-3.2 | B12: =VLOOKUP(A12,Лист1!B:C,2,0) -> Вырабатывает командную стратегию для достижения поставленной цели | C12: =IFERROR(SEARCH($A12,C$3),"") | D12: =IFERROR(SEARCH($A12,D$3),"") | E12: =IFERROR(SEARCH($A12,E$3),"") | F12: =IFERROR(SEARCH($A12,F$3),"") | G12: =IFERROR(SEARCH($A12,G$3),"") | H12: =IFERROR(SEARCH($A12,H$3),"") | I12: =IFERROR(SEARCH($A12,I$3),"") | J12: =IFERROR(SEARCH($A12,J$3),"") | ... U12: =IFERROR(SEARCH($A12,U$3),"") | V12: 9 | W12: =IFERROR(SEARCH($A12,W$3),"") | X12: =IFERROR(SEARCH($A12,X$3),"") | Y12: =IFERROR(SEARCH($A12,Y$3),"") | Z12: =IFERROR(SEARCH($A12,Z$3),"") | AA12: =IFERROR(SEARCH($A12,AA$3),"") | AB12: =IFERROR(SEARCH($A12,AB$3),"") | AC12: =IFERROR(SEARCH($A12,AC$3),"") | AD12: =IFERROR(SEARCH($A12,AD$3),"") | ... BA12: =IFERROR(SEARCH($A12,BA$3),"") | BB12: =SUM(C12:BA12) -> 9 | BC12: =IFERROR(SEARCH($A12,BC$3),"") | BD12: =IFERROR(SEARCH($A12,BD$3),"") | BE12: =SUM(BC12:BD12) -> 0 | BF12: =BB12+BE12 -> 9
A13: УК-4 | B13: =VLOOKUP(A13,Лист1!B:C,2,0) -> Способен осуществлять деловую коммуникацию в устной и письменной формах на государственном языке Российской Федерации и иностранном(ых) языке(ах) | C13: =IFERROR(IF(SEARCH($A13,C$3)<>0,1,""),"") | D13: =IFERROR(IF(SEARCH($A13,D$3)<>0,1,""),"") | E13: 18 | F13: =IFERROR(IF(SEARCH($A13,F$3)<>0,1,""),"") | G13: =IFERROR(IF(SEARCH($A13,G$3)<>0,1,""),"") | H13: =IFERROR(IF(SEARCH($A13,H$3)<>0,1,""),"") | I13: =IFERROR(IF(SEARCH($A13,I$3)<>0,1,""),"") | J13: =IFERROR(IF(SEARCH($A13,J$3)<>0,1,""),"") | K13: =IFERROR(IF(SEARCH($A13,K$3)<>0,1,""),"") | L13: =IFERROR(IF(SEARCH($A13,L$3)<>0,1,""),"") | M13: =IFERROR(IF(SEARCH($A13,M$3)<>0,1,""),"") | N13: =IFERROR(IF(SEARCH($A13,N$3)<>0,1,""),"") | O13: 18 | P13: =IFERROR(IF(SEARCH($A13,P$3)<>0,1,""),"") | Q13: =IFERROR(IF(SEARCH($A13,Q$3)<>0,1,""),"") | R13: =IFERROR(IF(SEARCH($A13,R$3)<>0,1,""),"") | S13: =IFERROR(IF(SEARCH($A13,S$3)<>0,1,""),"") | T13: =IFERROR(IF(SEARCH($A13,T$3)<>0,1,""),"") | U13: =IFERROR(IF(SEARCH($A13,U$3)<>0,1,""),"") | V13: =IFERROR(IF(SEARCH($A13,V$3)<>0,1,""),"") | W13: =IFERROR(IF(SEARCH($A13,W$3)<>0,1,""),"") | ... BA13: =IFERROR(IF(SEARCH($A13,BA$3)<>0,1,""),"") | BB13: =SUM(C13:BA13) -> 36 | BE13: =SUM(BC13:BD13) -> 0 | BF13: =BB13+BE13 -> 36
A14: УК-4.1 | B14: =VLOOKUP(A14,Лист1!B:C,2,0) -> Отбирает и использует средства русского языка в соответствии с языковыми нормами в целях построения эффективной академической и профессиональной коммуникации | C14: =IFERROR(SEARCH($A14,C$3),"") | D14: =IFERROR(SEARCH($A14,D$3),"") | E14: =IFERROR(SEARCH($A14,E$3),"") | F14: =IFERROR(SEARCH($A14,F$3),"") | G14: =IFERROR(SEARCH($A14,G$3),"") | H14: =IFERROR(SEARCH($A14,H$3),"") | I14: =IFERROR(SEARCH($A14,I$3),"") | J14: =IFERROR(SEARCH($A14,J$3),"") | ... N14: =IFERROR(SEARCH($A14,N$3),"") | O14: 9 | P14: =IFERROR(SEARCH($A14,P$3),"") | Q14: =IFERROR(SEARCH($A14,Q$3),"") | R14: =IFERROR(SEARCH($A14,R$3),"") | S14: =IFERROR(SEARCH($A14,S$3),"") | T14: =IFERROR(SEARCH($A14,T$3),"") | U14: =IFERROR(SEARCH($A14,U$3),"") | V14: =IFERROR(SEARCH($A14,V$3),"") | W14: =IFERROR(SEARCH($A14,W$3),"") | ... BA14: =IFERROR(SEARCH($A14,BA$3),"") | BB14: =SUM(C14:BA14) -> 9 | BC14: =IFERROR(SEARCH($A14,BC$3),"") | BD14: =IFERROR(SEARCH($A14,BD$3),"") | BE14: =SUM(BC14:BD14) -> 0 | BF14: =BB14+BE14 -> 9
A15: УК-4.2 | B15: =VLOOKUP(A15,Лист1!B:C,2,0) -> Осуществляет академическое и деловое взаимодействие в различных жанрах и формах с использованием современных коммуникативных технологий | C15: =IFERROR(SEARCH($A15,C$3),"") | D15: =IFERROR(SEARCH($A15,D$3),"") | E15: =IFERROR(SEARCH($A15,E$3),"") | F15: =IFERROR(SEARCH($A15,F$3),"") | G15: =IFERROR(SEARCH($A15,G$3),"") | H15: =IFERROR(SEARCH($A15,H$3),"") | I15: =IFERROR(SEARCH($A15,I$3),"") | J15: =IFERROR(SEARCH($A15,J$3),"") | ... BA15: =IFERROR(SEARCH($A15,BA$3),"") | BB15: =SUM(C15:BA15) -> 9 | BC15: =IFERROR(SEARCH($A15,BC$3),"") | BD15: =IFERROR(SEARCH($A15,BD$3),"") | BE15: =SUM(BC15:BD15) -> 0 | BF15: =BB15+BE15 -> 9
A16: УК-4.3 | B16: =VLOOKUP(A16,Лист1!B:C,2,0) -> Применяет современные коммуникативные технологии для академического взаимодействия на иностранном(ых) языке(ах) | C16: =IFERROR(SEARCH($A16,C$3),"") | D16: =IFERROR(SEARCH($A16,D$3),"") | E16: 9 | F16: =IFERROR(SEARCH($A16,F$3),"") | G16: =IFERROR(SEARCH($A16,G$3),"") | H16: =IFERROR(SEARCH($A16,H$3),"") | I16: =IFERROR(SEARCH($A16,I$3),"") | J16: =IFERROR(SEARCH($A16,J$3),"") | K16: =IFERROR(SEARCH($A16,K$3),"") | L16: =IFERROR(SEARCH($A16,L$3),"") | M16: =IFERROR(SEARCH($A16,M$3),"") | ... BA16: =IFERROR(SEARCH($A16,BA$3),"") | BB16: =SUM(C16:BA16) -> 9 | BC16: =IFERROR(SEARCH($A16,BC$3),"") | BD16: =IFERROR(SEARCH($A16,BD$3),"") | BE16: =SUM(BC16:BD16) -> 0 | BF16: =BB16+BE16 -> 9
A17: УК-4.4 | B17: =VLOOKUP(A17,Лист1!B:C,2,0) -> Применяет современные коммуникативные технологии для профессионального взаимодействия на иностранном(ых) языке(ах) | C17: =IFERROR(SEARCH($A17,C$3),"") | D17: =IFERROR(SEARCH($A17,D$3),"") | E17: 9 | F17: =IFERROR(SEARCH($A17,F$3),"") | G17: =IFERROR(SEARCH($A17,G$3),"") | H17: =IFERROR(SEARCH($A17,H$3),"") | I17: =IFERROR(SEARCH($A17,I$3),"") | J17: =IFERROR(SEARCH($A17,J$3),"") | K17: =IFERROR(SEARCH($A17,K$3),"") | L17: =IFERROR(SEARCH($A17,L$3),"") | M17: =IFERROR(SEARCH($A17,M$3),"") | ... BA17: =IFERROR(SEARCH($A17,BA$3),"") | BB17: =SUM(C17:BA17) -> 9 | BC17: =IFERROR(SEARCH($A17,BC$3),"") | BD17: =IFERROR(SEARCH($A17,BD$3),"") | BE17: =SUM(BC17:BD17) -> 0 | BF17: =BB17+BE17 -> 9
A18: УК-5 | B18: =VLOOKUP(A18,Лист1!B:C,2,0) -> Способен воспринимать межкультурное разнообразие общества в социально-историческом, этическом и философском контекстах | C18: =IFERROR(IF(SEARCH($A18,C$3)<>0,1,""),"") | D18: 18 | E18: =IFERROR(IF(SEARCH($A18,E$3)<>0,1,""),"") | F18: =IFERROR(IF(SEARCH($A18,F$3)<>0,1,""),"") | G18: =IFERROR(IF(SEARCH($A18,G$3)<>0,1,""),"") | H18: =IFERROR(IF(SEARCH($A18,H$3)<>0,1,""),"") | I18: =IFERROR(IF(SEARCH($A18,I$3)<>0,1,""),"") | J18: 18 | K18: =IFERROR(IF(SEARCH($A18,K$3)<>0,1,""),"") | L18: =IFERROR(IF(SEARCH($A18,L$3)<>0,1,""),"") | M18: =IFERROR(IF(SEARCH($A18,M$3)<>0,1,""),"") | N18: =IFERROR(IF(SEARCH($A18,N$3)<>0,1,""),"") | O18: =IFERROR(IF(SEARCH($A18,O$3)<>0,1,""),"") | P18: =IFERROR(IF(SEARCH($A18,P$3)<>0,1,""),"") | Q18: =IFERROR(IF(SEARCH($A18,Q$3)<>0,1,""),"") | R18: =IFERROR(IF(SEARCH($A18,R$3)<>0,1,""),"") | ... AB18: =IFERROR(IF(SEARCH($A18,AB$3)<>0,1,""),"") | AC18: 4 | AD18: =IFERROR(IF(SEARCH($A18,AD$3)<>0,1,""),"") | AE18: =IFERROR(IF(SEARCH($A18,AE$3)<>0,1,""),"") | AF18: =IFERROR(IF(SEARCH($A18,AF$3)<>0,1,""),"") | AG18: =IFERROR(IF(SEARCH($A18,AG$3)<>0,1,""),"") | AH18: =IFERROR(IF(SEARCH($A18,AH$3)<>0,1,""),"") | AI18: =IFERROR(IF(SEARCH($A18,AI$3)<>0,1,""),"") | AJ18: =IFERROR(IF(SEARCH($A18,AJ$3)<>0,1,""),"") | AK18: =IFERROR(IF(SEARCH($A18,AK$3)<>0,1,""),"") | ... BA18: =IFERROR(IF(SEARCH($A18,BA$3)<>0,1,""),"") | BB18: =SUM(C18:BA18) -> 40 | BC18: 18 | BD18: =IFERROR(SEARCH(_xlfn.CONCAT(" ",$A18),#REF!),"") | BE18: =SUM(BC18:BD18) -> 18 | BF18: =BB18+BE18 -> 58
A19: УК-5.1 | B19: =VLOOKUP(A19,Лист1!B:C,2,0) -> Анализирует идеологические и ценностные системы в контексте исторического развития общества, обосновывает актуальность их использования при социальном и профессиональном взаимодействии | C19: =IFERROR(SEARCH($A19,C$3),"") | D19: 9 | E19: =IFERROR(SEARCH($A19,E$3),"") | F19: =IFERROR(SEARCH($A19,F$3),"") | G19: =IFERROR(SEARCH($A19,G$3),"") | H19: =IFERROR(SEARCH($A19,H$3),"") | I19: =IFERROR(SEARCH($A19,I$3),"") | J19: =IFERROR(SEARCH($A19,J$3),"") | K19: =IFERROR(SEARCH($A19,K$3),"") | L19: =IFERROR(SEARCH($A19,L$3),"") | ... AB19: =IFERROR(SEARCH($A19,AB$3),"") | AC19: 2 | AD19: =IFERROR(SEARCH($A19,AD$3),"") | AE19: =IFERROR(SEARCH($A19,AE$3),"") | AF19: =IFERROR(SEARCH($A19,AF$3),"") | AG19: =IFERROR(SEARCH($A19,AG$3),"") | AH19: =IFERROR(SEARCH($A19,AH$3),"") | AI19: =IFERROR(SEARCH($A19,AI$3),"") | AJ19: =IFERROR(SEARCH($A19,AJ$3),"") | AK19: =IFERROR(SEARCH($A19,AK$3),"") | ... BA19: =IFERROR(SEARCH($A19,BA$3),"") | BB19: =SUM(C19:BA19) -> 11 | BC19: =IFERROR(SEARCH($A19,BC$3),"") | BD19: =IFERROR(SEARCH($A19,BD$3),"") | BE19: =SUM(BC19:BD19) -> 0 | BF19: =BB19+BE19 -> 11
A20: УК-5.2 | B20: =VLOOKUP(A20,Лист1!B:C,2,0) -> Выявляет современные тенденции исторического развития России с учетом геополитической обстановки | C20: =IFERROR(SEARCH($A20,C$3),"") | D20: =IFERROR(SEARCH($A20,D$3),"") -> 9 | E20: =IFERROR(SEARCH($A20,E$3),"") | F20: =IFERROR(SEARCH($A20,F$3),"") | G20: =IFERROR(SEARCH($A20,G$3),"") | H20: =IFERROR(SEARCH($A20,H$3),"") | I20: =IFERROR(SEARCH($A20,I$3),"") | J20: =IFERROR(SEARCH($A20,J$3),"") | ... AB20: =IFERROR(SEARCH($A20,AB$3),"") | AC20: 2 | AD20: =IFERROR(SEARCH($A20,AD$3),"") | AE20: =IFERROR(SEARCH($A20,AE$3),"") | AF20: =IFERROR(SEARCH($A20,AF$3),"") | AG20: =IFERROR(SEARCH($A20,AG$3),"") | AH20: =IFERROR(SEARCH($A20,AH$3),"") | AI20: =IFERROR(SEARCH($A20,AI$3),"") | AJ20: =IFERROR(SEARCH($A20,AJ$3),"") | AK20: =IFERROR(SEARCH($A20,AK$3),"") | ... BA20: =IFERROR(SEARCH($A20,BA$3),"") | BB20: =SUM(C20:BA20) -> 11 | BC20: =IFERROR(SEARCH($A20,BC$3),"") | BD20: =IFERROR(SEARCH($A20,BD$3),"") | BE20: =SUM(BC20:BD20) -> 0 | BF20: =BB20+BE20 -> 11
A21: УК-5.3 | B21: =VLOOKUP(A21,Лист1!B:C,2,0) -> Выстраивает социальное и профессиональное взаимодействие с учетом особенностей основных форм научного и религиозного сознания, деловой и общей культуры представителей различных социальных групп, этносов и конфессий | C21: =IFERROR(SEARCH($A21,C$3),"") | D21: =IFERROR(SEARCH($A21,D$3),"") | E21: =IFERROR(SEARCH($A21,E$3),"") | F21: =IFERROR(SEARCH($A21,F$3),"") | G21: =IFERROR(SEARCH($A21,G$3),"") | H21: =IFERROR(SEARCH($A21,H$3),"") | I21: =IFERROR(SEARCH($A21,I$3),"") | J21: 18 | K21: =IFERROR(SEARCH($A21,K$3),"") | L21: =IFERROR(SEARCH($A21,L$3),"") | M21: =IFERROR(SEARCH($A21,M$3),"") | N21: =IFERROR(SEARCH($A21,N$3),"") | O21: =IFERROR(SEARCH($A21,O$3),"") | P21: =IFERROR(SEARCH($A21,P$3),"") | Q21: =IFERROR(SEARCH($A21,Q$3),"") | R21: =IFERROR(SEARCH($A21,R$3),"") | ... BA21: =IFERROR(SEARCH($A21,BA$3),"") | BB21: =SUM(C21:BA21) -> 18 | BC21: 18 | BD21: =IFERROR(SEARCH($A21,BD$3),"") | BE21: =SUM(BC21:BD21) -> 18 | BF21: =BB21+BE21 -> 36
A22: УК-6 | B22: =VLOOKUP(A22,Лист1!B:C,2,0) -> Способен управлять своим временем, выстраивать и реализовывать траекторию саморазвития на основе принципов образования в течение всей жизни | C22: =IFERROR(IF(SEARCH($A22,C$3)<>0,1,""),"") | D22: =IFERROR(IF(SEARCH($A22,D$3)<>0,1,""),"") | E22: =IFERROR(IF(SEARCH($A22,E$3)<>0,1,""),"") | F22: =IFERROR(IF(SEARCH($A22,F$3)<>0,1,""),"") | G22: =IFERROR(IF(SEARCH($A22,G$3)<>0,1,""),"") | H22: =IFERROR(IF(SEARCH($A22,H$3)<>0,1,""),"") | I22: =IFERROR(IF(SEARCH($A22,I$3)<>0,1,""),"") | J22: =IFERROR(IF(SEARCH($A22,J$3)<>0,1,""),"") | K22: 18 | L22: =IFERROR(IF(SEARCH($A22,L$3)<>0,1,""),"") | M22: =IFERROR(IF(SEARCH($A22,M$3)<>0,1,""),"") | N22: =IFERROR(IF(SEARCH($A22,N$3)<>0,1,""),"") | O22: =IFERROR(IF(SEARCH($A22,O$3)<>0,1,""),"") | P22: =IFERROR(IF(SEARCH($A22,P$3)<>0,1,""),"") | Q22: =IFERROR(IF(SEARCH($A22,Q$3)<>0,1,""),"") | R22: =IFERROR(IF(SEARCH($A22,R$3)<>0,1,""),"") | S22: =IFERROR(IF(SEARCH($A22,S$3)<>0,1,""),"") | ... BA22: =IFERROR(IF(SEARCH($A22,BA$3)<>0,1,""),"") | BB22: =SUM(C22:BA22) -> 18 | BC22: =IFERROR(SEARCH(_xlfn.CONCAT(" ",$A22),#REF!),"") | BD22: =IFERROR(SEARCH(_xlfn.CONCAT(" ",$A22),#REF!),"") | BE22: =SUM(BC22:BD22) -> 0 | BF22: =BB22+BE22 -> 18
A23: УК-6.1 | B23: =VLOOKUP(A23,Лист1!B:C,2,0) -> Определяет цели и задачи саморазвития и профессионального роста на основе оценки временных и личностных ресурсов | C23: =IFERROR(SEARCH($A23,C$3),"") | D23: =IFERROR(SEARCH($A23,D$3),"") | E23: =IFERROR(SEARCH($A23,E$3),"") | F23: =IFERROR(SEARCH($A23,F$3),"") | G23: =IFERROR(SEARCH($A23,G$3),"") | H23: =IFERROR(SEARCH($A23,H$3),"") | I23: =IFERROR(SEARCH($A23,I$3),"") | J23: =IFERROR(SEARCH($A23,J$3),"") | K23: 9 | L23: =IFERROR(SEARCH($A23,L$3),"") | M23: =IFERROR(SEARCH($A23,M$3),"") | N23: =IFERROR(SEARCH($A23,N$3),"") | O23: =IFERROR(SEARCH($A23,O$3),"") | P23: =IFERROR(SEARCH($A23,P$3),"") | Q23: =IFERROR(SEARCH($A23,Q$3),"") | R23: =IFERROR(SEARCH($A23,R$3),"") | S23: =IFERROR(SEARCH($A23,S$3),"") | ... BA23: =IFERROR(SEARCH($A23,BA$3),"") | BB23: =SUM(C23:BA23) -> 9 | BC23: =IFERROR(SEARCH($A23,BC$3),"") | BD23: =IFERROR(SEARCH($A23,BD$3),"") | BE23: =SUM(BC23:BD23) -> 0 | BF23: =BB23+BE23 -> 9
A24: УК-6.2 | B24: =VLOOKUP(A24,Лист1!B:C,2,0) -> Использует основные возможности и инструменты непрерывного образования (образования в течение всей жизни) для реализации траектории саморазвития | C24: =IFERROR(SEARCH($A24,C$3),"") | D24: =IFERROR(SEARCH($A24,D$3),"") | E24: =IFERROR(SEARCH($A24,E$3),"") | F24: =IFERROR(SEARCH($A24,F$3),"") | G24: =IFERROR(SEARCH($A24,G$3),"") | H24: =IFERROR(SEARCH($A24,H$3),"") | I24: =IFERROR(SEARCH($A24,I$3),"") | J24: =IFERROR(SEARCH($A24,J$3),"") | ... BA24: =IFERROR(SEARCH($A24,BA$3),"") | BB24: =SUM(C24:BA24) -> 9 | BC24: =IFERROR(SEARCH($A24,BC$3),"") | BD24: =IFERROR(SEARCH($A24,BD$3),"") | BE24: =SUM(BC24:BD24) -> 0 | BF24: =BB24+BE24 -> 9
A25: УК-7 | B25: =VLOOKUP(A25,Лист1!B:C,2,0) -> Способен поддерживать должный уровень физической подготовленности для обеспечения полноценной социальной и профессиональной деятельности | C25: =IFERROR(IF(SEARCH($A25,C$3)<>0,1,""),"") | D25: =IFERROR(IF(SEARCH($A25,D$3)<>0,1,""),"") | E25: =IFERROR(IF(SEARCH($A25,E$3)<>0,1,""),"") | F25: =IFERROR(IF(SEARCH($A25,F$3)<>0,1,""),"") | G25: 18 | H25: =IFERROR(IF(SEARCH($A25,H$3)<>0,1,""),"") | I25: =IFERROR(IF(SEARCH($A25,I$3)<>0,1,""),"") | J25: =IFERROR(IF(SEARCH($A25,J$3)<>0,1,""),"") | K25: =IFERROR(IF(SEARCH($A25,K$3)<>0,1,""),"") | L25: =IFERROR(IF(SEARCH($A25,L$3)<>0,1,""),"") | M25: =IFERROR(IF(SEARCH($A25,M$3)<>0,1,""),"") | N25: =IFERROR(IF(SEARCH($A25,N$3)<>0,1,""),"") | O25: =IFERROR(IF(SEARCH($A25,O$3)<>0,1,""),"") | ... AC25: =IFERROR(IF(SEARCH($A25,AC$3)<>0,1,""),"") | AD25: 18 | AE25: =IFERROR(IF(SEARCH($A25,AE$3)<>0,1,""),"") | AF25: =IFERROR(IF(SEARCH($A25,AF$3)<>0,1,""),"") | AG25: =IFERROR(IF(SEARCH($A25,AG$3)<>0,1,""),"") | AH25: =IFERROR(IF(SEARCH($A25,AH$3)<>0,1,""),"") | AI25: =IFERROR(IF(SEARCH($A25,AI$3)<>0,1,""),"") | AJ25: =IFERROR(IF(SEARCH($A25,AJ$3)<>0,1,""),"") | AK25: =IFERROR(IF(SEARCH($A25,AK$3)<>0,1,""),"") | AL25: =IFERROR(IF(SEARCH($A25,AL$3)<>0,1,""),"") | ... BA25: =IFERROR(IF(SEARCH($A25,BA$3)<>0,1,""),"") | BB25: =SUM(C25:BA25) -> 36 | BE25: =SUM(BC25:BD25) -> 0 | BF25: =BB25+BE25 -> 36
A26: УК-7.1 | B26: =VLOOKUP(A26,Лист1!B:C,2,0) -> Идентифицирует и анализирует социально-биологические и методические основы физического воспитания, здорового образа жизни, профессионально-прикладной физической подготовки | C26: =IFERROR(SEARCH($A26,C$3),"") | D26: =IFERROR(SEARCH($A26,D$3),"") | E26: =IFERROR(SEARCH($A26,E$3),"") | F26: =IFERROR(SEARCH($A26,F$3),"") | G26: 9 | H26: =IFERROR(SEARCH($A26,H$3),"") | I26: =IFERROR(SEARCH($A26,I$3),"") | J26: =IFERROR(SEARCH($A26,J$3),"") | K26: =IFERROR(SEARCH($A26,K$3),"") | L26: =IFERROR(SEARCH($A26,L$3),"") | M26: =IFERROR(SEARCH($A26,M$3),"") | N26: =IFERROR(SEARCH($A26,N$3),"") | O26: =IFERROR(SEARCH($A26,O$3),"") | ... BA26: =IFERROR(SEARCH($A26,BA$3),"") | BB26: =SUM(C26:BA26) -> 9 | BC26: =IFERROR(SEARCH($A26,BC$3),"") | BD26: =IFERROR(SEARCH($A26,BD$3),"") | BE26: =SUM(BC26:BD26) -> 0 | BF26: =BB26+BE26 -> 9
A27: УК-7.2 | B27: =VLOOKUP(A27,Лист1!B:C,2,0) -> Выбирает способы оценки и контроля уровня физического развития, физической и профессионально-прикладной подготовленности, показателей работоспособности и здоровья, с учетом физиологических особенностей организма | C27: =IFERROR(SEARCH($A27,C$3),"") | D27: =IFERROR(SEARCH($A27,D$3),"") | E27: =IFERROR(SEARCH($A27,E$3),"") | F27: =IFERROR(SEARCH($A27,F$3),"") | G27: =IFERROR(SEARCH($A27,G$3),"") -> 9 | H27: =IFERROR(SEARCH($A27,H$3),"") | I27: =IFERROR(SEARCH($A27,I$3),"") | J27: =IFERROR(SEARCH($A27,J$3),"") | ... BA27: =IFERROR(SEARCH($A27,BA$3),"") | BB27: =SUM(C27:BA27) -> 9 | BC27: =IFERROR(SEARCH($A27,BC$3),"") | BD27: =IFERROR(SEARCH($A27,BD$3),"") | BE27: =SUM(BC27:BD27) -> 0 | BF27: =BB27+BE27 -> 9
A28: УК-7.3 | B28: =VLOOKUP(A28,Лист1!B:C,2,0) -> Соблюдает нормы здорового образа жизни, поддерживает должный уровень физической подготовленности для обеспечения полноценной социальной и профессиональной деятельности | C28: =IFERROR(SEARCH($A28,C$3),"") | D28: =IFERROR(SEARCH($A28,D$3),"") | E28: =IFERROR(SEARCH($A28,E$3),"") | F28: =IFERROR(SEARCH($A28,F$3),"") | G28: =IFERROR(SEARCH($A28,G$3),"") | H28: =IFERROR(SEARCH($A28,H$3),"") | I28: =IFERROR(SEARCH($A28,I$3),"") | J28: =IFERROR(SEARCH($A28,J$3),"") | ... AC28: =IFERROR(SEARCH($A28,AC$3),"") | AD28: 18 | AE28: =IFERROR(SEARCH($A28,AE$3),"") | AF28: =IFERROR(SEARCH($A28,AF$3),"") | AG28: =IFERROR(SEARCH($A28,AG$3),"") | AH28: =IFERROR(SEARCH($A28,AH$3),"") | AI28: =IFERROR(SEARCH($A28,AI$3),"") | AJ28: =IFERROR(SEARCH($A28,AJ$3),"") | AK28: =IFERROR(SEARCH($A28,AK$3),"") | AL28: =IFERROR(SEARCH($A28,AL$3),"") | ... BA28: =IFERROR(SEARCH($A28,BA$3),"") | BB28: =SUM(C28:BA28) -> 18 | BC28: =IFERROR(SEARCH($A28,BC$3),"") | BD28: =IFERROR(SEARCH($A28,BD$3),"") | BE28: =SUM(BC28:BD28) -> 0 | BF28: =BB28+BE28 -> 18
A29: УК-8 | B29: =VLOOKUP(A29,Лист1!B:C,2,0) -> Способен создавать и поддерживать в повседневной жизни и в профессиональной деятельности безопасные условия жизнедеятельности для сохранения природной среды, обеспечения устойчивого развития общества, в том числе при угрозе и возникновении чрезвычайных ситуаций и военных конфликтов | C29: =IFERROR(IF(SEARCH($A29,C$3)<>0,1,""),"") | D29: =IFERROR(IF(SEARCH($A29,D$3)<>0,1,""),"") | E29: =IFERROR(IF(SEARCH($A29,E$3)<>0,1,""),"") | F29: 18 | G29: =IFERROR(IF(SEARCH($A29,G$3)<>0,1,""),"") | H29: =IFERROR(IF(SEARCH($A29,H$3)<>0,1,""),"") | I29: =IFERROR(IF(SEARCH($A29,I$3)<>0,1,""),"") | J29: =IFERROR(IF(SEARCH($A29,J$3)<>0,1,""),"") | K29: =IFERROR(IF(SEARCH($A29,K$3)<>0,1,""),"") | L29: =IFERROR(IF(SEARCH($A29,L$3)<>0,1,""),"") | M29: =IFERROR(IF(SEARCH($A29,M$3)<>0,1,""),"") | N29: =IFERROR(IF(SEARCH($A29,N$3)<>0,1,""),"") | ... BA29: =IFERROR(IF(SEARCH($A29,BA$3)<>0,1,""),"") | BB29: =SUM(C29:BA29) -> 18 | BC29: =IFERROR(SEARCH(_xlfn.CONCAT(" ",$A29),#REF!),"") | BD29: =IFERROR(SEARCH(_xlfn.CONCAT(" ",$A29),#REF!),"") | BE29: =SUM(BC29:BD29) -> 0 | BF29: =BB29+BE29 -> 18
A30: УК-8.1 | B30: =VLOOKUP(A30,Лист1!B:C,2,0) -> Идентифицирует и анализирует факторы вредного влияния элементов среды обитания (технических средств, технологических процессов, материалов, зданий и сооружений, природных и социальных явлений) | C30: =IFERROR(SEARCH($A30,C$3),"") | D30: =IFERROR(SEARCH($A30,D$3),"") | E30: =IFERROR(SEARCH($A30,E$3),"") | F30: 6 | G30: =IFERROR(SEARCH($A30,G$3),"") | H30: =IFERROR(SEARCH($A30,H$3),"") | I30: =IFERROR(SEARCH($A30,I$3),"") | J30: =IFERROR(SEARCH($A30,J$3),"") | K30: =IFERROR(SEARCH($A30,K$3),"") | L30: =IFERROR(SEARCH($A30,L$3),"") | M30: =IFERROR(SEARCH($A30,M$3),"") | N30: =IFERROR(SEARCH($A30,N$3),"") | ... BA30: =IFERROR(SEARCH($A30,BA$3),"") | BB30: =SUM(C30:BA30) -> 6 | BC30: =IFERROR(SEARCH($A30,BC$3),"") | BD30: =IFERROR(SEARCH($A30,BD$3),"") | BE30: =SUM(BC30:BD30) -> 0 | BF30: =BB30+BE30 -> 6
A31: УК-8.2 | B31: =VLOOKUP(A31,Лист1!B:C,2,0) -> Определяет алгоритм действий по обеспечению безопасных условий жизнедеятельности при угрозе и возникновении чрезвычайных ситуаций и военных конфликтов | C31: =IFERROR(SEARCH($A31,C$3),"") | D31: =IFERROR(SEARCH($A31,D$3),"") | E31: =IFERROR(SEARCH($A31,E$3),"") | F31: 6 | G31: =IFERROR(SEARCH($A31,G$3),"") | H31: =IFERROR(SEARCH($A31,H$3),"") | I31: =IFERROR(SEARCH($A31,I$3),"") | J31: =IFERROR(SEARCH($A31,J$3),"") | K31: =IFERROR(SEARCH($A31,K$3),"") | L31: =IFERROR(SEARCH($A31,L$3),"") | M31: =IFERROR(SEARCH($A31,M$3),"") | N31: =IFERROR(SEARCH($A31,N$3),"") | ... BA31: =IFERROR(SEARCH($A31,BA$3),"") | BB31: =SUM(C31:BA31) -> 6 | BC31: =IFERROR(SEARCH($A31,BC$3),"") | BD31: =IFERROR(SEARCH($A31,BD$3),"") | BE31: =SUM(BC31:BD31) -> 0 | BF31: =BB31+BE31 -> 6
A32: УК-8.3 | B32: =VLOOKUP(A32,Лист1!B:C,2,0) -> Планирует мероприятия по организации безопасных условий труда на предприятии | C32: =IFERROR(SEARCH($A32,C$3),"") | D32: =IFERROR(SEARCH($A32,D$3),"") | E32: =IFERROR(SEARCH($A32,E$3),"") | F32: 6 | G32: =IFERROR(SEARCH($A32,G$3),"") | H32: =IFERROR(SEARCH($A32,H$3),"") | I32: =IFERROR(SEARCH($A32,I$3),"") | J32: =IFERROR(SEARCH($A32,J$3),"") | K32: =IFERROR(SEARCH($A32,K$3),"") | L32: =IFERROR(SEARCH($A32,L$3),"") | M32: =IFERROR(SEARCH($A32,M$3),"") | N32: =IFERROR(SEARCH($A32,N$3),"") | ... BA32: =IFERROR(SEARCH($A32,BA$3),"") | BB32: =SUM(C32:BA32) -> 6 | BC32: =IFERROR(SEARCH($A32,BC$3),"") | BD32: =IFERROR(SEARCH($A32,BD$3),"") | BE32: =SUM(BC32:BD32) -> 0 | BF32: =BB32+BE32 -> 6
A33: УК-9 | B33: =VLOOKUP(A33,Лист1!B:C,2,0) -> Способен использовать базовые дефектологические знания в социальной и профессиональной сферах | C33: =IFERROR(IF(SEARCH($A33,C$3)<>0,1,""),"") | D33: =IFERROR(IF(SEARCH($A33,D$3)<>0,1,""),"") | E33: =IFERROR(IF(SEARCH($A33,E$3)<>0,1,""),"") | F33: =IFERROR(IF(SEARCH($A33,F$3)<>0,1,""),"") | G33: =IFERROR(IF(SEARCH($A33,G$3)<>0,1,""),"") | H33: =IFERROR(IF(SEARCH($A33,H$3)<>0,1,""),"") | I33: =IFERROR(IF(SEARCH($A33,I$3)<>0,1,""),"") | J33: =IFERROR(IF(SEARCH($A33,J$3)<>0,1,""),"") | ... P33: =IFERROR(IF(SEARCH($A33,P$3)<>0,1,""),"") | Q33: 18 | R33: =IFERROR(IF(SEARCH($A33,R$3)<>0,1,""),"") | S33: =IFERROR(IF(SEARCH($A33,S$3)<>0,1,""),"") | T33: =IFERROR(IF(SEARCH($A33,T$3)<>0,1,""),"") | U33: =IFERROR(IF(SEARCH($A33,U$3)<>0,1,""),"") | V33: =IFERROR(IF(SEARCH($A33,V$3)<>0,1,""),"") | W33: =IFERROR(IF(SEARCH($A33,W$3)<>0,1,""),"") | X33: =IFERROR(IF(SEARCH($A33,X$3)<>0,1,""),"") | Y33: =IFERROR(IF(SEARCH($A33,Y$3)<>0,1,""),"") | ... BA33: =IFERROR(IF(SEARCH($A33,BA$3)<>0,1,""),"") | BB33: =SUM(C33:BA33) -> 18 | BC33: =IFERROR(SEARCH(_xlfn.CONCAT(" ",$A33),#REF!),"") | BD33: =IFERROR(SEARCH(_xlfn.CONCAT(" ",$A33),#REF!),"") | BE33: =SUM(BC33:BD33) -> 0 | BF33: =BB33+BE33 -> 18
A34: УК-9.1 | B34: =VLOOKUP(A34,Лист1!B:C,2,0) -> Осуществляет взаимодействие в социальной и профессиональной сферах с лицами с ограниченными возможностями здоровья и инвалидами | C34: =IFERROR(SEARCH($A34,C$3),"") | D34: =IFERROR(SEARCH($A34,D$3),"") | E34: =IFERROR(SEARCH($A34,E$3),"") | F34: =IFERROR(SEARCH($A34,F$3),"") | G34: =IFERROR(SEARCH($A34,G$3),"") | H34: =IFERROR(SEARCH($A34,H$3),"") | I34: =IFERROR(SEARCH($A34,I$3),"") | J34: =IFERROR(SEARCH($A34,J$3),"") | ... P34: =IFERROR(SEARCH($A34,P$3),"") | Q34: 9 | R34: =IFERROR(SEARCH($A34,R$3),"") | S34: =IFERROR(SEARCH($A34,S$3),"") | T34: =IFERROR(SEARCH($A34,T$3),"") | U34: =IFERROR(SEARCH($A34,U$3),"") | V34: =IFERROR(SEARCH($A34,V$3),"") | W34: =IFERROR(SEARCH($A34,W$3),"") | X34: =IFERROR(SEARCH($A34,X$3),"") | Y34: =IFERROR(SEARCH($A34,Y$3),"") | ... BA34: =IFERROR(SEARCH($A34,BA$3),"") | BB34: =SUM(C34:BA34) -> 9 | BC34: =IFERROR(SEARCH($A34,BC$3),"") | BD34: =IFERROR(SEARCH($A34,BD$3),"") | BE34: =SUM(BC34:BD34) -> 0 | BF34: =BB34+BE34 -> 9
A35: УК-9.2 | B35: =VLOOKUP(A35,Лист1!B:C,2,0) -> Планирует мероприятия по организации доступной среды на объектах транспорта для безбарьерного обслуживания пассажиров из числа инвалидов и лиц с ограниченными возможностями здоровья | C35: =IFERROR(SEARCH($A35,C$3),"") | D35: =IFERROR(SEARCH($A35,D$3),"") | E35: =IFERROR(SEARCH($A35,E$3),"") | F35: =IFERROR(SEARCH($A35,F$3),"") | G35: =IFERROR(SEARCH($A35,G$3),"") | H35: =IFERROR(SEARCH($A35,H$3),"") | I35: =IFERROR(SEARCH($A35,I$3),"") | J35: =IFERROR(SEARCH($A35,J$3),"") | ... BA35: =IFERROR(SEARCH($A35,BA$3),"") | BB35: =SUM(C35:BA35) -> 9 | BC35: =IFERROR(SEARCH($A35,BC$3),"") | BD35: =IFERROR(SEARCH($A35,BD$3),"") | BE35: =SUM(BC35:BD35) -> 0 | BF35: =BB35+BE35 -> 9
A36: УК-10 | B36: =VLOOKUP(A36,Лист1!B:C,2,0) -> Способен принимать обоснованные экономические решения в различных областях жизнедеятельности | C36: =IFERROR(IF(SEARCH($A36,C$3)<>0,1,""),"") | D36: =IFERROR(IF(SEARCH($A36,D$3)<>0,1,""),"") | E36: =IFERROR(IF(SEARCH($A36,E$3)<>0,1,""),"") | F36: =IFERROR(IF(SEARCH($A36,F$3)<>0,1,""),"") | G36: =IFERROR(IF(SEARCH($A36,G$3)<>0,1,""),"") | H36: =IFERROR(IF(SEARCH($A36,H$3)<>0,1,""),"") | I36: =IFERROR(IF(SEARCH($A36,I$3)<>0,1,""),"") | J36: =IFERROR(IF(SEARCH($A36,J$3)<>0,1,""),"") | ... S36: =IFERROR(IF(SEARCH($A36,S$3)<>0,1,""),"") | T36: 18 | U36: =IFERROR(IF(SEARCH($A36,U$3)<>0,1,""),"") | V36: =IFERROR(IF(SEARCH($A36,V$3)<>0,1,""),"") | W36: =IFERROR(IF(SEARCH($A36,W$3)<>0,1,""),"") | X36: =IFERROR(IF(SEARCH($A36,X$3)<>0,1,""),"") | Y36: =IFERROR(IF(SEARCH($A36,Y$3)<>0,1,""),"") | Z36: =IFERROR(IF(SEARCH($A36,Z$3)<>0,1,""),"") | AA36: =IFERROR(IF(SEARCH($A36,AA$3)<>0,1,""),"") | AB36: =IFERROR(IF(SEARCH($A36,AB$3)<>0,1,""),"") | ... BA36: =IFERROR(IF(SEARCH($A36,BA$3)<>0,1,""),"") | BB36: =SUM(C36:BA36) -> 18 | BE36: =SUM(BC36:BD36) -> 0 | BF36: =BB36+BE36 -> 18
A37: УК-10.1 | B37: =VLOOKUP(A37,Лист1!B:C,2,0) -> Анализирует и критически оценивает информацию, необходимую для принятия обоснованных экономических решений | C37: =IFERROR(SEARCH($A37,C$3),"") | D37: =IFERROR(SEARCH($A37,D$3),"") | E37: =IFERROR(SEARCH($A37,E$3),"") | F37: =IFERROR(SEARCH($A37,F$3),"") | G37: =IFERROR(SEARCH($A37,G$3),"") | H37: =IFERROR(SEARCH($A37,H$3),"") | I37: =IFERROR(SEARCH($A37,I$3),"") | J37: =IFERROR(SEARCH($A37,J$3),"") | ... S37: =IFERROR(SEARCH($A37,S$3),"") | T37: 9 | U37: =IFERROR(SEARCH($A37,U$3),"") | V37: =IFERROR(SEARCH($A37,V$3),"") | W37: =IFERROR(SEARCH($A37,W$3),"") | X37: =IFERROR(SEARCH($A37,X$3),"") | Y37: =IFERROR(SEARCH($A37,Y$3),"") | Z37: =IFERROR(SEARCH($A37,Z$3),"") | AA37: =IFERROR(SEARCH($A37,AA$3),"") | AB37: =IFERROR(SEARCH($A37,AB$3),"") | ... BA37: =IFERROR(SEARCH($A37,BA$3),"") | BB37: =SUM(C37:BA37) -> 9 | BC37: =IFERROR(SEARCH($A37,BC$3),"") | BD37: =IFERROR(SEARCH($A37,BD$3),"") | BE37: =SUM(BC37:BD37) -> 0 | BF37: =BB37+BE37 -> 9
A38: УК-10.2 | B38: =VLOOKUP(A38,Лист1!B:C,2,0) -> Применяет методы личного экономического и финансового планирования для достижения текущих и долгосрочных финансовых целей, использует финансовые инструменты для управления личными финансами (личным бюджетом), контролирует собственные экономические и финансовые риски | C38: =IFERROR(SEARCH($A38,C$3),"") | D38: =IFERROR(SEARCH($A38,D$3),"") | E38: =IFERROR(SEARCH($A38,E$3),"") | F38: =IFERROR(SEARCH($A38,F$3),"") | G38: =IFERROR(SEARCH($A38,G$3),"") | H38: =IFERROR(SEARCH($A38,H$3),"") | I38: =IFERROR(SEARCH($A38,I$3),"") | J38: =IFERROR(SEARCH($A38,J$3),"") | ... S38: =IFERROR(SEARCH($A38,S$3),"") | T38: 9 | U38: =IFERROR(SEARCH($A38,U$3),"") | V38: =IFERROR(SEARCH($A38,V$3),"") | W38: =IFERROR(SEARCH($A38,W$3),"") | X38: =IFERROR(SEARCH($A38,X$3),"") | Y38: =IFERROR(SEARCH($A38,Y$3),"") | Z38: =IFERROR(SEARCH($A38,Z$3),"") | AA38: =IFERROR(SEARCH($A38,AA$3),"") | AB38: =IFERROR(SEARCH($A38,AB$3),"") | ... BA38: =IFERROR(SEARCH($A38,BA$3),"") | BB38: =SUM(C38:BA38) -> 9 | BC38: =IFERROR(SEARCH($A38,BC$3),"") | BD38: =IFERROR(SEARCH($A38,BD$3),"") | BE38: =SUM(BC38:BD38) -> 0 | BF38: =BB38+BE38 -> 9
A39: УК-11 | B39: =VLOOKUP(A39,Лист1!B:C,2,0) -> Способен формировать нетерпимое отношение к проявлениям экстремизма, терроризма, коррупционному поведению и противодействовать им в профессиональной деятельности | C39: =IFERROR(IF(SEARCH($A39,C$3)<>0,1,""),"") | D39: =IFERROR(IF(SEARCH($A39,D$3)<>0,1,""),"") | E39: =IFERROR(IF(SEARCH($A39,E$3)<>0,1,""),"") | F39: =IFERROR(IF(SEARCH($A39,F$3)<>0,1,""),"") | G39: =IFERROR(IF(SEARCH($A39,G$3)<>0,1,""),"") | H39: =IFERROR(IF(SEARCH($A39,H$3)<>0,1,""),"") | I39: =IFERROR(IF(SEARCH($A39,I$3)<>0,1,""),"") | J39: =IFERROR(IF(SEARCH($A39,J$3)<>0,1,""),"") | ... Q39: =IFERROR(IF(SEARCH($A39,Q$3)<>0,1,""),"") | R39: 18 | S39: =IFERROR(IF(SEARCH($A39,S$3)<>0,1,""),"") | T39: =IFERROR(IF(SEARCH($A39,T$3)<>0,1,""),"") | U39: =IFERROR(IF(SEARCH($A39,U$3)<>0,1,""),"") | V39: =IFERROR(IF(SEARCH($A39,V$3)<>0,1,""),"") | W39: =IFERROR(IF(SEARCH($A39,W$3)<>0,1,""),"") | X39: =IFERROR(IF(SEARCH($A39,X$3)<>0,1,""),"") | Y39: =IFERROR(IF(SEARCH($A39,Y$3)<>0,1,""),"") | Z39: =IFERROR(IF(SEARCH($A39,Z$3)<>0,1,""),"") | ... BA39: =IFERROR(IF(SEARCH($A39,BA$3)<>0,1,""),"") | BB39: =SUM(C39:BA39) -> 18 | BC39: =IFERROR(SEARCH(_xlfn.CONCAT(" ",$A39),#REF!),"") | BD39: =IFERROR(SEARCH(_xlfn.CONCAT(" ",$A39),#REF!),"") | BE39: =SUM(BC39:BD39) -> 0 | BF39: =BB39+BE39 -> 18
A40: УК-11.1 | B40: =VLOOKUP(A40,Лист1!B:C,2,0) -> Раскрывает механизм проявления коррупционного поведения и определяет способы противодействия ему в профессиональной деятельности | C40: =IFERROR(SEARCH($A40,C$3),"") | D40: =IFERROR(SEARCH($A40,D$3),"") | E40: =IFERROR(SEARCH($A40,E$3),"") | F40: =IFERROR(SEARCH($A40,F$3),"") | G40: =IFERROR(SEARCH($A40,G$3),"") | H40: =IFERROR(SEARCH($A40,H$3),"") | I40: =IFERROR(SEARCH($A40,I$3),"") | J40: =IFERROR(SEARCH($A40,J$3),"") | ... BA40: =IFERROR(SEARCH($A40,BA$3),"") | BB40: =SUM(C40:BA40) -> 9 | BC40: =IFERROR(SEARCH($A40,BC$3),"") | BD40: =IFERROR(SEARCH($A40,BD$3),"") | BE40: =SUM(BC40:BD40) -> 0 | BF40: =BB40+BE40 -> 9
...

Sheet Лист1
A1: УК-1 | B1: УК-1 | C1: =VLOOKUP(B1,F:G,2,0) -> Способен осуществлять поиск, критический анализ и синтез информации, применять системный подход для решения поставленных задач | D1: Индекс | G1: Содержание
B2: УК-1.1 | C2: =VLOOKUP(B2,F:G,2,0) -> Осуществляет поиск информации, критически оценивает надежность источников информации, работает с противоречивой информацией из разных источников | D2: УК-1 | F2: =_xlfn.CONCAT(D2,E2) -> УК-1 | G2: Способен осуществлять поиск, критический анализ и синтез информации, применять системный подход для решения поставленных задач
B3: УК-1.2 | C3: =VLOOKUP(B3,F:G,2,0) -> Анализирует проблемную ситуацию, выявляет ее составляющие и связи между ними, формулирует и аргументирует выводы и суждения | E3: УК-1.1 | F3: =_xlfn.CONCAT(D3,E3) -> УК-1.1 | G3: Осуществляет поиск информации, критически оценивает надежность источников информации, работает с противоречивой информацией из разных источников
A4: УК-2 | B4: УК-2 | C4: =VLOOKUP(B4,F:G,2,0) -> Способен определять круг задач в рамках поставленной цели и выбирать оптимальные способы их решения, исходя из действующих правовых норм, имеющихся ресурсов и ограничений | F4: =_xlfn.CONCAT(D4,E4) | G4: Философия
B5: УК-2.1 | C5: =VLOOKUP(B5,F:G,2,0) -> Решает ситуационные задачи с учетом трудовых и социальных факторов в рамках нормативно-правового регулирования | F5: =_xlfn.CONCAT(D5,E5) | G5: Выполнение, подготовка к процедуре защиты и защита выпускной квалификационной работы
B6: УК-2.2 | C6: =VLOOKUP(B6,F:G,2,0) -> Формулирует проектную задачу, определяет способы ее решения средствами проектного управления | E6: УК-1.2 | F6: =_xlfn.CONCAT(D6,E6) -> УК-1.2 | G6: Анализирует проблемную ситуацию, выявляет ее составляющие и связи между ними, формулирует и аргументирует выводы и суждения
A7: УК-3 | B7: УК-3 | C7: =VLOOKUP(B7,F:G,2,0) -> Способен осуществлять социальное взаимодействие и реализовывать свою роль в команде | F7: =_xlfn.CONCAT(D7,E7) | G7: Философия
B8: УК-3.1 | C8: =VLOOKUP(B8,F:G,2,0) -> Организует и координирует работу команды с учетом интересов, особенностей поведения и мнения её членов | F8: =_xlfn.CONCAT(D8,E8) | G8: Выполнение, подготовка к процедуре защиты и защита выпускной квалификационной работы
B9: УК-3.2 | C9: =VLOOKUP(B9,F:G,2,0) -> Вырабатывает командную стратегию для достижения поставленной цели | D9: УК-2 | F9: =_xlfn.CONCAT(D9,E9) -> УК-2 | G9: Способен определять круг задач в рамках поставленной цели и выбирать оптимальные способы их решения, исходя из действующих правовых норм, имеющихся ресурсов и ограничений
A10: УК-4 | B10: УК-4 | C10: =VLOOKUP(B10,F:G,2,0) -> Способен осуществлять деловую коммуникацию в устной и письменной формах на государственном языке Российской Федерации и иностранном(ых) языке(ах) | E10: УК-2.1 | F10: =_xlfn.CONCAT(D10,E10) -> УК-2.1 | G10: Решает ситуационные задачи с учетом трудовых и социальных факторов в рамках нормативно-правового регулирования
B11: УК-4.1 | C11: =VLOOKUP(B11,F:G,2,0) -> Отбирает и использует средства русского языка в соответствии с языковыми нормами в целях построения эффективной академической и профессиональной коммуникации | F11: =_xlfn.CONCAT(D11,E11) | G11: Правовое обеспечение профессиональной деятельности
B12: УК-4.2 | C12: =VLOOKUP(B12,F:G,2,0) -> Осуществляет академическое и деловое взаимодействие в различных жанрах и формах с использованием современных коммуникативных технологий | F12: =_xlfn.CONCAT(D12,E12) | G12: История России
B13: УК-4.3 | C13: =VLOOKUP(B13,F:G,2,0) -> Применяет современные коммуникативные технологии для академического взаимодействия на иностранном(ых) языке(ах) | F13: =_xlfn.CONCAT(D13,E13) | G13: Выполнение, подготовка к процедуре защиты и защита выпускной квалификационной работы
B14: УК-4.4 | C14: =VLOOKUP(B14,F:G,2,0) -> Применяет современные коммуникативные технологии для профессионального взаимодействия на иностранном(ых) языке(ах) | E14: УК-2.2 | F14: =_xlfn.CONCAT(D14,E14) -> УК-2.2 | G14: Формулирует проектную задачу, определяет способы ее решения средствами проектного управления
A15: УК-5 | B15: УК-5 | C15: =VLOOKUP(B15,F:G,2,0) -> Способен воспринимать межкультурное разнообразие общества в социально-историческом, этическом и философском контекстах | F15: =_xlfn.CONCAT(D15,E15) | G15: Менеджмент
B16: УК-5.1 | C16: =VLOOKUP(B16,F:G,2,0) -> Анализирует идеологические и ценностные системы в контексте исторического развития общества, обосновывает актуальность их использования при социальном и профессиональном взаимодействии | F16: =_xlfn.CONCAT(D16,E16) | G16: Выполнение, подготовка к процедуре защиты и защита выпускной квалификационной работы
B17: УК-5.2 | C17: =VLOOKUP(B17,F:G,2,0) -> Выявляет современные тенденции исторического развития России с учетом геополитической обстановки | F17: =_xlfn.CONCAT(D17,E17) | G17: Построение бизнес-модели
B18: УК-5.3 | C18: =VLOOKUP(B18,F:G,2,0) -> Выстраивает социальное и профессиональное взаимодействие с учетом особенностей основных форм научного и религиозного сознания, деловой и общей культуры представителей различных социальных групп, этносов и конфессий | D18: УК-3 | F18: =_xlfn.CONCAT(D18,E18) -> УК-3 | G18: Способен осуществлять социальное взаимодействие и реализовывать свою роль в команде
A19: УК-6 | B19: УК-6 | C19: =VLOOKUP(B19,F:G,2,0) -> Способен управлять своим временем, выстраивать и реализовывать траекторию саморазвития на основе принципов образования в течение всей жизни | E19: УК-3.1 | F19: =_xlfn.CONCAT(D19,E19) -> УК-3.1 | G19: Организует и координирует работу команды с учетом интересов, особенностей поведения и мнения её членов
B20: УК-6.1 | C20: =VLOOKUP(B20,F:G,2,0) -> Определяет цели и задачи саморазвития и профессионального роста на основе оценки временных и личностных ресурсов | F20: =_xlfn.CONCAT(D20,E20) | G20: Менеджмент
B21: УК-6.2 | C21: =VLOOKUP(B21,F:G,2,0) -> Использует основные возможности и инструменты непрерывного образования (образования в течение всей жизни) для реализации траектории саморазвития | F21: =_xlfn.CONCAT(D21,E21) | G21: Выполнение, подготовка к процедуре защиты и защита выпускной квалификационной работы
A22: УК-7 | B22: УК-7 | C22: =VLOOKUP(B22,F:G,2,0) -> Способен поддерживать должный уровень физической подготовленности для обеспечения полноценной социальной и профессиональной деятельности | E22: УК-3.2 | F22: =_xlfn.CONCAT(D22,E22) -> УК-3.2 | G22: Вырабатывает командную стратегию для достижения поставленной цели
B23: УК-7.1 | C23: =VLOOKUP(B23,F:G,2,0) -> Идентифицирует и анализирует социально-биологические и методические основы физического воспитания, здорового образа жизни, профессионально-прикладной физической подготовки | F23: =_xlfn.CONCAT(D23,E23) | G23: Менеджмент
B24: УК-7.2 | C24: =VLOOKUP(B24,F:G,2,0) -> Выбирает способы оценки и контроля уровня физического развития, физической и профессионально-прикладной подготовленности, показателей работоспособности и здоровья, с учетом физиологических особенностей организма | F24: =_xlfn.CONCAT(D24,E24) | G24: Выполнение, подготовка к процедуре защиты и защита выпускной квалификационной работы
B25: УК-7.3 | C25: =VLOOKUP(B25,F:G,2,0) -> Соблюдает нормы здорового образа жизни, поддерживает должный уровень физической подготовленности для обеспечения полноценной социальной и профессиональной деятельности | D25: УК-4 | F25: =_xlfn.CONCAT(D25,E25) -> УК-4 | G25: Способен осуществлять деловую коммуникацию в устной и письменной формах на государственном языке Российской Федерации и иностранном(ых) языке(ах)
A26: УК-8 | B26: УК-8 | C26: =VLOOKUP(B26,F:G,2,0) -> Способен создавать и поддерживать в повседневной жизни и в профессиональной деятельности безопасные условия жизнедеятельности для сохранения природной среды, обеспечения устойчивого развития общества, в том числе при угрозе и возникновении чрезвычайных ситуаций и военных конфликтов | E26: УК-4.1 | F26: =_xlfn.CONCAT(D26,E26) -> УК-4.1 | G26: Отбирает и использует средства русского языка в соответствии с языковыми нормами в целях построения эффективной академической и профессиональной коммуникации
B27: УК-8.1 | C27: =VLOOKUP(B27,F:G,2,0) -> Идентифицирует и анализирует факторы вредного влияния элементов среды обитания (технических средств, технологических процессов, материалов, зданий и сооружений, природных и социальных явлений) | F27: =_xlfn.CONCAT(D27,E27) | G27: Русский язык и деловые коммуникации
B28: УК-8.2 | C28: =VLOOKUP(B28,F:G,2,0) -> Определяет алгоритм действий по обеспечению безопасных условий жизнедеятельности при угрозе и возникновении чрезвычайных ситуаций и военных конфликтов | F28: =_xlfn.CONCAT(D28,E28) | G28: Выполнение, подготовка к процедуре защиты и защита выпускной квалификационной работы
B29: УК-8.3 | C29: =VLOOKUP(B29,F:G,2,0) -> Планирует мероприятия по организации безопасных условий труда на предприятии | E29: УК-4.2 | F29: =_xlfn.CONCAT(D29,E29) -> УК-4.2 | G29: Осуществляет академическое и деловое взаимодействие в различных жанрах и формах с использованием современных коммуникативных технологий
A30: УК-9 | B30: УК-9 | C30: =VLOOKUP(B30,F:G,2,0) -> Способен использовать базовые дефектологические знания в социальной и профессиональной сферах | F30: =_xlfn.CONCAT(D30,E30) | G30: Русский язык и деловые коммуникации
B31: УК-9.1 | C31: =VLOOKUP(B31,F:G,2,0) -> Осуществляет взаимодействие в социальной и профессиональной сферах с лицами с ограниченными возможностями здоровья и инвалидами | F31: =_xlfn.CONCAT(D31,E31) | G31: Выполнение, подготовка к процедуре защиты и защита выпускной квалификационной работы
B32: УК-9.2 | C32: =VLOOKUP(B32,F:G,2,0) -> Планирует мероприятия по организации доступной среды на объектах транспорта для безбарьерного обслуживания пассажиров из числа инвалидов и лиц с ограниченными возможностями здоровья | E32: УК-4.3 | F32: =_xlfn.CONCAT(D32,E32) -> УК-4.3 | G32: Применяет современные коммуникативные технологии для академического взаимодействия на иностранном(ых) языке(ах)
A33: УК-10 | B33: УК-10 | C33: =VLOOKUP(B33,F:G,2,0) -> Способен принимать обоснованные экономические решения в различных областях жизнедеятельности | F33: =_xlfn.CONCAT(D33,E33) | G33: Иностранный язык
B34: УК-10.1 | C34: =VLOOKUP(B34,F:G,2,0) -> Анализирует и критически оценивает информацию, необходимую для принятия обоснованных экономических решений | F34: =_xlfn.CONCAT(D34,E34) | G34: Выполнение, подготовка к процедуре защиты и защита выпускной квалификационной работы
B35: УК-10.2 | C35: =VLOOKUP(B35,F:G,2,0) -> Применяет методы личного экономического и финансового планирования для достижения текущих и долгосрочных финансовых целей, использует финансовые инструменты для управления личными финансами (личным бюджетом), контролирует собственные экономические и финансовые риски | E35: УК-4.4 | F35: =_xlfn.CONCAT(D35,E35) -> УК-4.4 | G35: Применяет современные коммуникативные технологии для профессионального взаимодействия на иностранном(ых) языке(ах)
A36: УК-11 | B36: УК-11 | C36: =VLOOKUP(B36,F:G,2,0) -> Способен формировать нетерпимое отношение к проявлениям экстремизма, терроризма, коррупционному поведению и противодействовать им в профессиональной деятельности | F36: =_xlfn.CONCAT(D36,E36) | G36: Иностранный язык
B37: УК-11.1 | C37: =VLOOKUP(B37,F:G,2,0) -> Раскрывает механизм проявления коррупционного поведения и определяет способы противодействия ему в профессиональной деятельности | F37: =_xlfn.CONCAT(D37,E37) | G37: Выполнение, подготовка к процедуре защиты и защита выпускной квалификационной работы
B38: УК-11.2 | C38: =VLOOKUP(B38,F:G,2,0) -> Обосновывает правовыми средствами свою гражданскую позицию в отношении терроризма и экстремизма и применяет способы противодействия им в профессиональной сфере | D38: УК-5 | F38: =_xlfn.CONCAT(D38,E38) -> УК-5 | G38: Способен воспринимать межкультурное разнообразие общества в социально-историческом, этическом и философском контекстах
B39: ОПК-1 | C39: =VLOOKUP(B39,F:G,2,0) -> Способен применять естественнонаучные и общеинженерные знания, методы математического анализа и моделирования в профессиональной деятельности | E39: УК-5.1 | F39: =_xlfn.CONCAT(D39,E39) -> УК-5.1 | G39: Анализирует идеологические и ценностные системы в контексте исторического развития общества, обосновывает актуальность их использования при социальном и профессиональном взаимодействии
B40: ОПК-1.1 | C40: =VLOOKUP(B40,F:G,2,0) -> Применяет методы высшей математики для решения задач профессиональной деятельности | F40: =_xlfn.CONCAT(D40,E40) | G40: История (история России, всеобщая история)
...

Sheet Матрица
C1: Все индикаторы дисциплины | G1: 7 | K1: 1 | L1: 2 | M1: 3 | N1: 4 | O1: 5 | P1: 6 | Q1: 7 | R1: 8 | S1: 9 | T1: 10 | U1: 11 | V1: 12 | W1: 13 | X1: 14 | Y1: 15 | Z1: 16 | AA1: 17 | AB1: 18 | AC1: 19 | AD1: 20 | AE1: 21 | AF1: 22 | AG1: 23 | AH1: 24 | AI1: 25
C2: =HLOOKUP($G$1,$K$1:$AI$4,4,0) -> ОПК-3.1; ПК-2.1; ПК-2.2 | G2: =_xlfn.CONCAT(HLOOKUP($G$1,$K$1:$AI$4,3,0)," ",HLOOKUP($G$1,$K$1:$AI$4,2,0)) -> Б1.О.07 Экономика транспортных систем | I2: Индекс | J2: Содержание | K2: Деловые коммуникации (билингвальный курс) | L2: Психологические основы интеллектуально-личностного развития | M2: Проектно-процессное управление | N2: Правовое обеспечение транспортных процессов | O2: Стратегические решения в функциональных областях организации | P2: Научно-техническое обеспечение технологических процессов на транспорте | Q2: Экономика транспортных систем | R2: Математическое моделирование в профессиональной деятельности | S2: Системы искусственного интеллекта | T2: Цифровые технологии в науке и на транспорте | U2: Коммерческая деятельность на транспорте | V2: Управление процессами перевозок | W2: Технология работы единой транспортной системы | X2: Организация мультимодальных и интермодальных перевозок | Y2: Транспортное и складское обеспечение логистики | Z2: Мультимодальные транспортно-логистические центры | AA2: Актово-претензионное дело | AB2: Стандартизация и сертификация транспортных услуг | AC2: Учебная практика (ознакомительная практика) | AD2: Производственная практика (научно-исследовательская работа) | AE2: Производственная практика (технологическая (производственно-технологическая) практика) | AF2: Производственная практика (эксплуатационная практика) | AG2: Итого без учета факультативов | AH2: Клиентоориентированность на транспорте | AI2: Развитие семейного сознания личности
A3: Компетенция (код) | B3: Компетенция (расшифровка) | C3: Индикатор (код) | D3: Индикатор (расшифровка) | E3: Компетенция (объединенная) | F3: Индикатор (объединенный) | G3: Название дисциплины | H3: Количество вопросов | K3: Б1.О.01 | L3: Б1.О.02 | M3: Б1.О.03 | N3: Б1.О.04 | O3: Б1.О.05 | P3: Б1.О.06 | Q3: Б1.О.07 | R3: Б1.О.08 | S3: Б1.О.09.01 | T3: Б1.О.09.02 | U3: Б1.В.01 | V3: Б1.В.02 | W3: Б1.В.ДВ.01.01 | X3: Б1.В.ДВ.01.02 | Y3: Б1.В.ДВ.02.01 | Z3: Б1.В.ДВ.02.02 | AA3: Б1.В.ДВ.03.01 | AB3: Б1.В.ДВ.03.02 | AC3: Б2.О.01(У) | AD3: Б2.О.02(Н) | AE3: Б2.В.01(П) | AF3: Б2.В.02(П) | AH3: ФТД.01 | AI3: ФТД.02
A4: =IFERROR(LEFT(C4,SEARCH(".",C4)-1),"") -> ОПК-3 | B4: =IFERROR(VLOOKUP(A4,$I$5:$J$54,2,0),"") -> Способен управлять жизненным циклом инженерных продуктов с учетом экономических, экологических и социальных ограничений | C4: {=_xlfn.TEXTSPLIT(C2,," ")} -> ОПК-3.1; | D4: =IFERROR(VLOOKUP(IF(RIGHT(C4,1)<>";",C4,LEFT(C4,LEN(C4)-1)),$I$5:$J$54,2,0),"") -> Анализирует стадии жизненного цикла инженерных продуктов и подходы к экономической оценке их стоимости | E4: =_xlfn.CONCAT(A4," ",B4) -> ОПК-3 Способен управлять жизненным циклом инженерных продуктов с учетом экономических, экологических и социальных ограничений | F4: =_xlfn.CONCAT(IF(RIGHT(C4,1)<>";",C4,LEFT(C4,LEN(C4)-1))," ",D4) -> ОПК-3.1 Анализирует стадии жизненного цикла инженерных продуктов и подходы к экономической оценке их стоимости | G4: =$G$2 -> Б1.О.07 Экономика транспортных систем | H4: =IFERROR(VLOOKUP(IF(RIGHT(C4,1)<>";",C4,LEFT(C4,LEN(C4)-1)),$I$5:$AI$54,$G$1+2,0),"") -> 10 | K4: УК-4.1; УК-4.2; УК-5.1; УК-5.2 | L4: УК-1.1; УК-1.2; УК-6.1; УК-6.2 | M4: УК-2.1; УК-2.2; УК-3.1; УК-3.2 | N4: ОПК-6.1 | O4: ОПК-2.1; ОПК-2.2; ОПК-3.2; ОПК-6.2 | P4: ОПК-1.1; ОПК-4.1; ОПК-4.2 | Q4: ОПК-3.1; ПК-2.1; ПК-2.2 | R4: ОПК-1.2 | S4: ОПК-5.3 | T4: ОПК-5.1; ОПК-5.2 | U4: ПК-3.1; ПК-3.2 | V4: ПК-1.1 | W4: ПК-1.3 | X4: ПК-1.3 | Y4: ПК-1.2 | Z4: ПК-1.2 | AA4: ПК-4.1; ПК-4.2 | AB4: ПК-4.1; ПК-4.2 | AC4: ОПК-3.1; ПК-1.1 | AD4: ОПК-4.1; ПК-2.1 | AE4: ПК-1.2; ПК-1.3; ПК-4.1; ПК-4.2 | AF4: ПК-2.2; ПК-3.1; ПК-3.2 | AH4: ПК-1.1 | AI4: УК-5.1
A5: =IFERROR(LEFT(C5,SEARCH(".",C5)-1),"") -> ПК-2 | B5: =IFERROR(VLOOKUP(A5,$I$5:$J$54,2,0),"") -> Способен осуществлять контроль ключевых финансовых показателей логистической деятельности по перевозке груза в цепи поставок | C5: ПК-2.1; | D5: =IFERROR(VLOOKUP(IF(RIGHT(C5,1)<>";",C5,LEFT(C5,LEN(C5)-1)),$I$5:$J$54,2,0),"") -> Анализирует финансовую информацию и разрабатывает план мероприятий по достижению финансовых показателей деятельности по перевозке грузов в рамках цепей поставок | E5: =_xlfn.CONCAT(A5," ",B5) -> ПК-2 Способен осуществлять контроль ключевых финансовых показателей логистической деятельности по перевозке груза в цепи поставок | F5: =_xlfn.CONCAT(IF(RIGHT(C5,1)<>";",C5,LEFT(C5,LEN(C5)-1))," ",D5) -> ПК-2.1 Анализирует финансовую информацию и разрабатывает план мероприятий по достижению финансовых показателей деятельности по перевозке грузов в рамках цепей поставок | G5: =IF(F5<>" ",$G$2,"") -> Б1.О.07 Экономика транспортных систем | H5: =IFERROR(VLOOKUP(IF(RIGHT(C5,1)<>";",C5,LEFT(C5,LEN(C5)-1)),$I$5:$AI$54,$G$1+2,0),"") -> 6 | I5: УК-1 | J5: Способен осуществлять критический анализ проблемных ситуаций на основе системного подхода, вырабатывать стратегию действий | L5: 16 | AG5: =SUM(S5:AF5) -> 0
